<?xml version="1.0" encoding="utf-8"?>
<!-- Generated from embodiments/arx_x5/X5A.urdf for XPolicyLab dual_x5.yml. -->
<robot name="dual_x5_exact_from_x5a">
  <link name="footprint"/>

  <!-- Dummy movable joints keep HoloBrain default joint ids compatible:
       fl_joint1..6 -> [10..15], fr_joint1..6 -> [18..23]. -->
  <link name="dummy_link_0"/>
  <joint name="dummy_joint_0" type="continuous"><parent link="footprint"/><child link="dummy_link_0"/><origin xyz="0 0 0" rpy="0 0 0"/><axis xyz="0 0 1"/></joint>
  <link name="dummy_link_1"/>
  <joint name="dummy_joint_1" type="continuous"><parent link="dummy_link_0"/><child link="dummy_link_1"/><origin xyz="0 0 0" rpy="0 0 0"/><axis xyz="0 0 1"/></joint>
  <link name="dummy_link_2"/>
  <joint name="dummy_joint_2" type="continuous"><parent link="dummy_link_1"/><child link="dummy_link_2"/><origin xyz="0 0 0" rpy="0 0 0"/><axis xyz="0 0 1"/></joint>
  <link name="dummy_link_3"/>
  <joint name="dummy_joint_3" type="continuous"><parent link="dummy_link_2"/><child link="dummy_link_3"/><origin xyz="0 0 0" rpy="0 0 0"/><axis xyz="0 0 1"/></joint>
  <link name="dummy_link_4"/>
  <joint name="dummy_joint_4" type="continuous"><parent link="dummy_link_3"/><child link="dummy_link_4"/><origin xyz="0 0 0" rpy="0 0 0"/><axis xyz="0 0 1"/></joint>
  <link name="dummy_link_5"/>
  <joint name="dummy_joint_5" type="continuous"><parent link="dummy_link_4"/><child link="dummy_link_5"/><origin xyz="0 0 0" rpy="0 0 0"/><axis xyz="0 0 1"/></joint>
  <link name="dummy_link_6"/>
  <joint name="dummy_joint_6" type="continuous"><parent link="dummy_link_5"/><child link="dummy_link_6"/><origin xyz="0 0 0" rpy="0 0 0"/><axis xyz="0 0 1"/></joint>
  <link name="dummy_link_7"/>
  <joint name="dummy_joint_7" type="continuous"><parent link="dummy_link_6"/><child link="dummy_link_7"/><origin xyz="0 0 0" rpy="0 0 0"/><axis xyz="0 0 1"/></joint>
  <link name="dummy_link_8"/>
  <joint name="dummy_joint_8" type="continuous"><parent link="dummy_link_7"/><child link="dummy_link_8"/><origin xyz="0 0 0" rpy="0 0 0"/><axis xyz="0 0 1"/></joint>
  <link name="dummy_link_9"/>
  <joint name="dummy_joint_9" type="continuous"><parent link="dummy_link_8"/><child link="dummy_link_9"/><origin xyz="0 0 0" rpy="0 0 0"/><axis xyz="0 0 1"/></joint>

  <joint name="fl_base_joint" type="fixed"><parent link="footprint"/><child link="fl_base_link"/><origin xyz="0.2 0.3 0.765" rpy="0 0 0"/></joint>
<link name="fl_base_link">
    <inertial>
      <origin xyz="-3.0001E-05 3.0589E-05 0.027324" rpy="0 0 0" />
      <mass value="0.43995" />
      <inertia ixx="0.00017" ixy="0.00000" ixz="0.00000" iyy="0.00017" iyz="0.00000" izz="0.00016" />
    </inertial>
    <visual>
      <origin xyz="0 0 0" rpy="0 0 0" />
      <geometry>
        <mesh filename="meshes/base_link.STL" />
      </geometry>
      <material name="black">
        <color rgba="0 0 0 1" />
      </material>
    </visual>
    <collision>
      <origin xyz="0 0 0" rpy="0 0 0" />
      <geometry>
        <mesh filename="meshes/base_link.STL" />
      </geometry>
    </collision>
  </link>
  <link name="fl_link1">
    <inertial>
      <origin xyz="0.0054231 -0.0080289 0.017086" rpy="0 0 0" />
      <mass value="0.066982" />
      <inertia ixx="0.00008" ixy="0.00000" ixz="0.00001" iyy="0.00003" iyz="0.00000" izz="0.00008" />
    </inertial>
    <visual>
      <origin xyz="0 0 0" rpy="0 0 0" />
      <geometry>
        <mesh filename="meshes/link1.STL" />
      </geometry>
      <material name="black">
        <color rgba="0 0 0 1" />
      </material>
    </visual>
    <collision>
      <origin xyz="0 0 0" rpy="0 0 0" />
      <geometry>
        <mesh filename="meshes/link1.STL" />
      </geometry>
    </collision>
  </link>
  <joint name="fl_joint1" type="revolute">
    <origin xyz="0 0 0.0605" rpy="0 0 0" />
    <parent link="fl_base_link" />
    <child link="fl_link1" />
    <axis xyz="0 0 1" />
    <limit lower="-10" upper="10" effort="100" velocity="1000" />
  </joint>
  <link name="fl_link2">
    <inertial>
      <origin xyz="-0.13237 0.0020852 0.00010549" rpy="0 0 0" />
      <mass value="1.0795" />
      <inertia ixx="0.00051" ixy="0.00001" ixz="-0.00004" iyy="0.01599" iyz="0.00000" izz="0.01605" />
    </inertial>
    <visual>
      <origin xyz="0 0 0" rpy="0 0 0" />
      <geometry>
        <mesh filename="meshes/link2.STL" />
      </geometry>
      <material name="black">
        <color rgba="0 0 0 1" />
      </material>
    </visual>
    <collision>
      <origin xyz="0 0 0" rpy="0 0 0" />
      <geometry>
        <mesh filename="meshes/link2.STL" />
      </geometry>
    </collision>
  </link>
  <joint name="fl_joint2" type="revolute">
    <origin xyz="0.02 0 0.04" rpy="0 0 0" />
    <parent link="fl_link1" />
    <child link="fl_link2" />
    <axis xyz="0 1 0" />
    <limit lower="-10" upper="10" effort="100" velocity="1000" />
  </joint>
  <link name="fl_link3">
    <inertial>
      <origin xyz="0.18531 0.00068376 -0.051638" rpy="0 0 0" />
      <mass value="0.54534" />
      <inertia ixx="0.00036" ixy="-0.00003" ixz="-0.00039" iyy="0.00423" iyz="0.00001" izz="0.00420" />
    </inertial>
    <visual>
      <origin xyz="0 0 0" rpy="0 0 0" />
      <geometry>
        <mesh filename="meshes/link3.STL" />
      </geometry>
      <material name="white">
        <color rgba="1 1 1 1" />
      </material>
    </visual>
    <collision>
      <origin xyz="0 0 0" rpy="0 0 0" />
      <geometry>
        <mesh filename="meshes/link3.STL" />
      </geometry>
    </collision>
  </link>
  <joint name="fl_joint3" type="revolute">
    <origin xyz="-0.264 0 0" rpy="3.1416 0 0" />
    <parent link="fl_link2" />
    <child link="fl_link3" />
    <axis xyz="0 1 0" />
    <limit lower="-10" upper="10" effort="100" velocity="1000" />
  </joint>
  <link name="fl_link4">
    <inertial>
      <origin xyz="0.040231 0.0044807 -0.035335" rpy="0 0 0" />
      <mass value="0.11714" />
      <inertia ixx="0.00019" ixy="-0.00002" ixz="-0.00009" iyy="0.00023" iyz="0.00002" izz="0.00014" />
    </inertial>
    <visual>
      <origin xyz="0 0 0" rpy="0 0 0" />
      <geometry>
        <mesh filename="meshes/link4.STL" />
      </geometry>
      <material name="black">
        <color rgba="0 0 0 1" />
      </material>
    </visual>
    <collision>
      <origin xyz="0 0 0" rpy="0 0 0" />
      <geometry>
        <mesh filename="meshes/link4.STL" />
      </geometry>
    </collision>
  </link>
  <joint name="fl_joint4" type="revolute">
    <origin xyz="0.245 0 -0.056" rpy="0 0 0" />
    <parent link="fl_link3" />
    <child link="fl_link4" />
    <axis xyz="0 1 0" />
    <limit lower="-10" upper="10" effort="100" velocity="1000" />
  </joint>
  <link name="fl_link5">
    <inertial>
      <origin xyz="0.003612 -1.5455E-05 0.055214" rpy="0 0 0" />
      <mass value="0.63488" />
      <inertia ixx="0.00083" ixy="0.00000" ixz="0.00007" iyy="0.00082" iyz="0.00000" izz="0.00026" />
    </inertial>
    <visual>
      <origin xyz="0 0 0" rpy="0 0 0" />
      <geometry>
        <mesh filename="meshes/link5.STL" />
      </geometry>
      <material name="black">
        <color rgba="0 0 0 1" />
      </material>
    </visual>
    <collision>
      <origin xyz="0 0 0" rpy="0 0 0" />
      <geometry>
        <mesh filename="meshes/link5.STL" />
      </geometry>
    </collision>
  </link>
  <joint name="fl_joint5" type="revolute">
    <origin xyz="0.06775 0.0005 -0.0865" rpy="0 0 0" />
    <parent link="fl_link4" />
    <child link="fl_link5" />
    <axis xyz="0 0 1" />
    <limit lower="-10" upper="10" effort="100" velocity="1000" />
  </joint>
  <link name="fl_link6">
    <inertial>
      <origin xyz="0.041697 2.4368E-05 0.00014464" rpy="0 0 0" />
      <mass value="0.44089" />
      <inertia ixx="0.00038" ixy="0.00000" ixz="0.00000" iyy="0.00028" iyz="0.00000" izz="0.00050" />
    </inertial>
    <visual>
      <origin xyz="0 0 0" rpy="0 0 0" />
      <geometry>
        <mesh filename="meshes/link6.STL" />
      </geometry>
      <material name="black">
        <color rgba="0 0 0 1" />
      </material>
    </visual>
    <collision>
      <origin xyz="0 0 0" rpy="0 0 0" />
      <geometry>
        <mesh filename="meshes/link6.STL" />
      </geometry>
    </collision>
  </link>
  <joint name="fl_joint6" type="revolute">
    <origin xyz="0.02895 0 0.0865" rpy="-3.1416 0 0" />
    <parent link="fl_link5" />
    <child link="fl_link6" />
    <axis xyz="1 0 0" />
    <limit lower="-3.14" upper="3.14" effort="100" velocity="1000" />
  </joint>

  <link name="fl_camera_base">
    <visual>
      <origin xyz="0 0 0.0" rpy="0 0 0"/>
      <geometry>
        <mesh filename="meshes/camera_base.glb" />
      </geometry>
    </visual>
  </link>
  <joint name="fl_hand_to_camera_mount" type="fixed">
    <parent link="fl_link6"/>
    <child link="fl_camera_base"/>
    <origin xyz="0.057 0 0" rpy="0 0 -3.1416"/>
  </joint>

  <link name="fl_camera">
    <visual>
      <origin rpy="0.0 0.0 -1.5707963267948966" xyz="0.0 0.0 -0.0"/>
      <geometry>
        <mesh filename="meshes/camera.glb" />
      </geometry>
    </visual>
  </link>
  <joint name="fl_camera_joint" type="fixed">
    <parent link="fl_camera_base"/>
    <child link="fl_camera"/>
    <origin xyz="-0.0275 0.0 0.05" rpy="0 0.3491 3.141592653589793"/>
  </joint> 

  <link name="fl_link7">
    <inertial>
      <origin xyz="-0.00035522 -0.007827 -0.0029883" rpy="0 0 0" />
      <mass value="0.064798" />
      <inertia ixx="0.00002" ixy="0.00000" ixz="0.00000" iyy="0.00003" iyz="0.00000" izz="0.00003" />
    </inertial>
    <visual>
      <origin xyz="0 0 0" rpy="0 0 0" />
      <geometry>
        <mesh filename="meshes/link7.STL" />
      </geometry>
      <material name="black">
        <color rgba="0 0 0 1" />
      </material>
    </visual>
    <collision>
      <origin xyz="0 0 0" rpy="0 0 0" />
      <geometry>
        <mesh filename="meshes/link7.STL" />
      </geometry>
    </collision>
  </link>
  <joint name="fl_joint7" type="prismatic">
    <origin xyz="0.08657 0.024896 -0.0002436" rpy="0 0 0" />
    <parent link="fl_link6" />
    <child link="fl_link7" />
    <axis xyz="0 1 0" />
    <limit lower="0" upper="0.044" effort="100" velocity="1000" />
  </joint>
  <link name="fl_link8">
    <inertial>
      <origin xyz="-0.00035522 0.0078277 0.0024201" rpy="0 0 0" />
      <mass value="0.064798" />
      <inertia ixx="0.00002" ixy="0.00000" ixz="0.00000" iyy="0.00003" iyz="0.00000" izz="0.00003" />
    </inertial>
    <visual>
      <origin xyz="0 0 0" rpy="0 0 0" />
      <geometry>
        <mesh filename="meshes/link8.STL" />
      </geometry>
      <material name="black">
        <color rgba="0 0 0 1" />
      </material>
    </visual>
    <collision>
      <origin xyz="0 0 0" rpy="0 0 0" />
      <geometry>
        <mesh filename="meshes/link8.STL" />
      </geometry>
    </collision>
  </link>
  <joint name="fl_joint8" type="prismatic">
    <origin xyz="0.08657 -0.0249 -0.00024366" rpy="0 0 0" />
    <parent link="fl_link6" />
    <child link="fl_link8" />
    <axis xyz="0 -1 0" />
    <limit lower="0" upper="0.044" effort="100" velocity="1000" />
  </joint>

  <joint name="fr_base_joint" type="fixed"><parent link="footprint"/><child link="fr_base_link"/><origin xyz="0.2 -0.3 0.765" rpy="0 0 0"/></joint>
<link name="fr_base_link">
    <inertial>
      <origin xyz="-3.0001E-05 3.0589E-05 0.027324" rpy="0 0 0" />
      <mass value="0.43995" />
      <inertia ixx="0.00017" ixy="0.00000" ixz="0.00000" iyy="0.00017" iyz="0.00000" izz="0.00016" />
    </inertial>
    <visual>
      <origin xyz="0 0 0" rpy="0 0 0" />
      <geometry>
        <mesh filename="meshes/base_link.STL" />
      </geometry>
      <material name="black">
        <color rgba="0 0 0 1" />
      </material>
    </visual>
    <collision>
      <origin xyz="0 0 0" rpy="0 0 0" />
      <geometry>
        <mesh filename="meshes/base_link.STL" />
      </geometry>
    </collision>
  </link>
  <link name="fr_link1">
    <inertial>
      <origin xyz="0.0054231 -0.0080289 0.017086" rpy="0 0 0" />
      <mass value="0.066982" />
      <inertia ixx="0.00008" ixy="0.00000" ixz="0.00001" iyy="0.00003" iyz="0.00000" izz="0.00008" />
    </inertial>
    <visual>
      <origin xyz="0 0 0" rpy="0 0 0" />
      <geometry>
        <mesh filename="meshes/link1.STL" />
      </geometry>
      <material name="black">
        <color rgba="0 0 0 1" />
      </material>
    </visual>
    <collision>
      <origin xyz="0 0 0" rpy="0 0 0" />
      <geometry>
        <mesh filename="meshes/link1.STL" />
      </geometry>
    </collision>
  </link>
  <joint name="fr_joint1" type="revolute">
    <origin xyz="0 0 0.0605" rpy="0 0 0" />
    <parent link="fr_base_link" />
    <child link="fr_link1" />
    <axis xyz="0 0 1" />
    <limit lower="-10" upper="10" effort="100" velocity="1000" />
  </joint>
  <link name="fr_link2">
    <inertial>
      <origin xyz="-0.13237 0.0020852 0.00010549" rpy="0 0 0" />
      <mass value="1.0795" />
      <inertia ixx="0.00051" ixy="0.00001" ixz="-0.00004" iyy="0.01599" iyz="0.00000" izz="0.01605" />
    </inertial>
    <visual>
      <origin xyz="0 0 0" rpy="0 0 0" />
      <geometry>
        <mesh filename="meshes/link2.STL" />
      </geometry>
      <material name="black">
        <color rgba="0 0 0 1" />
      </material>
    </visual>
    <collision>
      <origin xyz="0 0 0" rpy="0 0 0" />
      <geometry>
        <mesh filename="meshes/link2.STL" />
      </geometry>
    </collision>
  </link>
  <joint name="fr_joint2" type="revolute">
    <origin xyz="0.02 0 0.04" rpy="0 0 0" />
    <parent link="fr_link1" />
    <child link="fr_link2" />
    <axis xyz="0 1 0" />
    <limit lower="-10" upper="10" effort="100" velocity="1000" />
  </joint>
  <link name="fr_link3">
    <inertial>
      <origin xyz="0.18531 0.00068376 -0.051638" rpy="0 0 0" />
      <mass value="0.54534" />
      <inertia ixx="0.00036" ixy="-0.00003" ixz="-0.00039" iyy="0.00423" iyz="0.00001" izz="0.00420" />
    </inertial>
    <visual>
      <origin xyz="0 0 0" rpy="0 0 0" />
      <geometry>
        <mesh filename="meshes/link3.STL" />
      </geometry>
      <material name="white">
        <color rgba="1 1 1 1" />
      </material>
    </visual>
    <collision>
      <origin xyz="0 0 0" rpy="0 0 0" />
      <geometry>
        <mesh filename="meshes/link3.STL" />
      </geometry>
    </collision>
  </link>
  <joint name="fr_joint3" type="revolute">
    <origin xyz="-0.264 0 0" rpy="3.1416 0 0" />
    <parent link="fr_link2" />
    <child link="fr_link3" />
    <axis xyz="0 1 0" />
    <limit lower="-10" upper="10" effort="100" velocity="1000" />
  </joint>
  <link name="fr_link4">
    <inertial>
      <origin xyz="0.040231 0.0044807 -0.035335" rpy="0 0 0" />
      <mass value="0.11714" />
      <inertia ixx="0.00019" ixy="-0.00002" ixz="-0.00009" iyy="0.00023" iyz="0.00002" izz="0.00014" />
    </inertial>
    <visual>
      <origin xyz="0 0 0" rpy="0 0 0" />
      <geometry>
        <mesh filename="meshes/link4.STL" />
      </geometry>
      <material name="black">
        <color rgba="0 0 0 1" />
      </material>
    </visual>
    <collision>
      <origin xyz="0 0 0" rpy="0 0 0" />
      <geometry>
        <mesh filename="meshes/link4.STL" />
      </geometry>
    </collision>
  </link>
  <joint name="fr_joint4" type="revolute">
    <origin xyz="0.245 0 -0.056" rpy="0 0 0" />
    <parent link="fr_link3" />
    <child link="fr_link4" />
    <axis xyz="0 1 0" />
    <limit lower="-10" upper="10" effort="100" velocity="1000" />
  </joint>
  <link name="fr_link5">
    <inertial>
      <origin xyz="0.003612 -1.5455E-05 0.055214" rpy="0 0 0" />
      <mass value="0.63488" />
      <inertia ixx="0.00083" ixy="0.00000" ixz="0.00007" iyy="0.00082" iyz="0.00000" izz="0.00026" />
    </inertial>
    <visual>
      <origin xyz="0 0 0" rpy="0 0 0" />
      <geometry>
        <mesh filename="meshes/link5.STL" />
      </geometry>
      <material name="black">
        <color rgba="0 0 0 1" />
      </material>
    </visual>
    <collision>
      <origin xyz="0 0 0" rpy="0 0 0" />
      <geometry>
        <mesh filename="meshes/link5.STL" />
      </geometry>
    </collision>
  </link>
  <joint name="fr_joint5" type="revolute">
    <origin xyz="0.06775 0.0005 -0.0865" rpy="0 0 0" />
    <parent link="fr_link4" />
    <child link="fr_link5" />
    <axis xyz="0 0 1" />
    <limit lower="-10" upper="10" effort="100" velocity="1000" />
  </joint>
  <link name="fr_link6">
    <inertial>
      <origin xyz="0.041697 2.4368E-05 0.00014464" rpy="0 0 0" />
      <mass value="0.44089" />
      <inertia ixx="0.00038" ixy="0.00000" ixz="0.00000" iyy="0.00028" iyz="0.00000" izz="0.00050" />
    </inertial>
    <visual>
      <origin xyz="0 0 0" rpy="0 0 0" />
      <geometry>
        <mesh filename="meshes/link6.STL" />
      </geometry>
      <material name="black">
        <color rgba="0 0 0 1" />
      </material>
    </visual>
    <collision>
      <origin xyz="0 0 0" rpy="0 0 0" />
      <geometry>
        <mesh filename="meshes/link6.STL" />
      </geometry>
    </collision>
  </link>
  <joint name="fr_joint6" type="revolute">
    <origin xyz="0.02895 0 0.0865" rpy="-3.1416 0 0" />
    <parent link="fr_link5" />
    <child link="fr_link6" />
    <axis xyz="1 0 0" />
    <limit lower="-3.14" upper="3.14" effort="100" velocity="1000" />
  </joint>

  <link name="fr_camera_base">
    <visual>
      <origin xyz="0 0 0.0" rpy="0 0 0"/>
      <geometry>
        <mesh filename="meshes/camera_base.glb" />
      </geometry>
    </visual>
  </link>
  <joint name="fr_hand_to_camera_mount" type="fixed">
    <parent link="fr_link6"/>
    <child link="fr_camera_base"/>
    <origin xyz="0.057 0 0" rpy="0 0 -3.1416"/>
  </joint>

  <link name="fr_camera">
    <visual>
      <origin rpy="0.0 0.0 -1.5707963267948966" xyz="0.0 0.0 -0.0"/>
      <geometry>
        <mesh filename="meshes/camera.glb" />
      </geometry>
    </visual>
  </link>
  <joint name="fr_camera_joint" type="fixed">
    <parent link="fr_camera_base"/>
    <child link="fr_camera"/>
    <origin xyz="-0.0275 0.0 0.05" rpy="0 0.3491 3.141592653589793"/>
  </joint> 

  <link name="fr_link7">
    <inertial>
      <origin xyz="-0.00035522 -0.007827 -0.0029883" rpy="0 0 0" />
      <mass value="0.064798" />
      <inertia ixx="0.00002" ixy="0.00000" ixz="0.00000" iyy="0.00003" iyz="0.00000" izz="0.00003" />
    </inertial>
    <visual>
      <origin xyz="0 0 0" rpy="0 0 0" />
      <geometry>
        <mesh filename="meshes/link7.STL" />
      </geometry>
      <material name="black">
        <color rgba="0 0 0 1" />
      </material>
    </visual>
    <collision>
      <origin xyz="0 0 0" rpy="0 0 0" />
      <geometry>
        <mesh filename="meshes/link7.STL" />
      </geometry>
    </collision>
  </link>
  <joint name="fr_joint7" type="prismatic">
    <origin xyz="0.08657 0.024896 -0.0002436" rpy="0 0 0" />
    <parent link="fr_link6" />
    <child link="fr_link7" />
    <axis xyz="0 1 0" />
    <limit lower="0" upper="0.044" effort="100" velocity="1000" />
  </joint>
  <link name="fr_link8">
    <inertial>
      <origin xyz="-0.00035522 0.0078277 0.0024201" rpy="0 0 0" />
      <mass value="0.064798" />
      <inertia ixx="0.00002" ixy="0.00000" ixz="0.00000" iyy="0.00003" iyz="0.00000" izz="0.00003" />
    </inertial>
    <visual>
      <origin xyz="0 0 0" rpy="0 0 0" />
      <geometry>
        <mesh filename="meshes/link8.STL" />
      </geometry>
      <material name="black">
        <color rgba="0 0 0 1" />
      </material>
    </visual>
    <collision>
      <origin xyz="0 0 0" rpy="0 0 0" />
      <geometry>
        <mesh filename="meshes/link8.STL" />
      </geometry>
    </collision>
  </link>
  <joint name="fr_joint8" type="prismatic">
    <origin xyz="0.08657 -0.0249 -0.00024366" rpy="0 0 0" />
    <parent link="fr_link6" />
    <child link="fr_link8" />
    <axis xyz="0 -1 0" />
    <limit lower="0" upper="0.044" effort="100" velocity="1000" />
  </joint>
</robot>
